Workbook

Sheet Person_Data
A1: person_id | B1: department | C1: rank | D1: total_military_service_years | E1: success_rate | F1: total_flight_hours | G1: medal_count | H1: risk_score
A2: AO07216 | B2: Alpha | C2: Lieutenant Colonel | D2: 19.13 | E2: 0.55555556 | F2: 131.7 | G2: 0 | H2: 83.9
A3: AO12605 | B3: Alpha | C3: Major | D3: 14.03 | F3: 2167.6 | G3: 2 | H3: 58.2
A4: AO17018 | B4: Alpha | C4: Captain | D4: 8.69 | E4: 1 | F4: 1232.2 | G4: 2 | H4: 60.3
A5: G22139 | B5: Alpha | C5: Warrant Officer | D5: 4.01 | F5: 0 | G5: 4 | H5: 55.4
A6: AO16543 | B6: Alpha | C6: Captain | D6: 9.6 | F6: 0 | G6: 2 | H6: 48.1
A7: AO22963 | B7: Alpha | C7: Senior Lieutenant | D7: 4.44 | E7: 0.95454545 | F7: 1786.6 | G7: 3 | H7: 25.7
A8: AO19391 | B8: Alpha | C8: Captain | D8: 7.03 | E8: 0.8 | F8: 654.7 | G8: 3 | H8: 33.7
A9: AO18976 | B9: Alpha | C9: Captain | D9: 8.36 | E9: 1 | F9: 624.7 | G9: 1 | H9: 31.2
A10: AO13357 | B10: Alpha | C10: Major | D10: 13.01 | E10: 0.5 | F10: 1279.8 | G10: 6 | H10: 58.6
A11: AO23290 | B11: Alpha | C11: Lieutenant | D11: 2.69 | E11: 0.83333333 | F11: 778 | G11: 1 | H11: 47.1
A12: AO16547 | B12: Alpha | C12: Captain | D12: 9.92 | E12: 0.25 | F12: 415.5 | G12: 0 | H12: 69.1
A13: AO13497 | B13: Alpha | C13: Major | D13: 13.14 | E13: 0.84210526 | F13: 1122.4 | G13: 2 | H13: 51.3
A14: AO17259 | B14: Alpha | C14: Captain | D14: 9.47 | E14: 0.83333333 | F14: 1332.4 | G14: 0 | H14: 48.3
A15: AO21304 | B15: Alpha | C15: Senior Lieutenant | D15: 5.41 | E15: 0.86363636 | F15: 3414.7 | G15: 2 | H15: 43.3
A16: AO24033 | B16: Alpha | C16: Lieutenant | D16: 1.58 | E16: 0.85714286 | F16: 392.8 | G16: 3 | H16: 41.3
A17: AO25712 | B17: Alpha | C17: Lieutenant | D17: 1.2 | E17: 0.875 | F17: 340 | G17: 4 | H17: 24.8
A18: AO21586 | B18: Alpha | C18: Senior Lieutenant | D18: 4.73 | E18: 0.61904762 | F18: 1864.6 | G18: 2 | H18: 37.7
A19: AO24023 | B19: Alpha | C19: Lieutenant | D19: 1.53 | F19: 291.7 | G19: 4 | H19: 52
A20: AO21458 | B20: Alpha | C20: Senior Lieutenant | D20: 5.22 | E20: 0.66666667 | F20: 643.8 | G20: 2 | H20: 37.9
A21: AO18524 | B21: Alpha | C21: Captain | D21: 7.65 | F21: 0 | G21: 3 | H21: 45.3
A22: AO12328 | B22: Alpha | C22: Major | D22: 13.92 | F22: 0 | G22: 5 | H22: 46.4
A23: AO16636 | B23: Alpha | C23: Captain | D23: 10.37 | F23: 0 | G23: 0 | H23: 54.6
A24: AO25389 | B24: Alpha | C24: Lieutenant | D24: 1.06 | F24: 0 | G24: 0 | H24: 57.4
A25: AO25228 | B25: Alpha | C25: Lieutenant | D25: 1.42 | F25: 0 | G25: 0 | H25: 56.8
A26: AO18688 | B26: Alpha | C26: Captain | D26: 8.26 | F26: 0 | G26: 0 | H26: 44.9
A27: AO20164 | B27: Alpha | C27: Senior Lieutenant | D27: 5.83 | E27: 0.85185185 | F27: 2127.1 | G27: 0 | H27: 63.3
A28: AO25328 | B28: Alpha | C28: Lieutenant | D28: 1.49 | E28: 1 | F28: 273.3 | G28: 2 | H28: 32.7
A29: AO24416 | B29: Alpha | C29: Lieutenant | D29: 2.17 | E29: 1 | F29: 546.7 | G29: 4 | H29: 36.7
A30: AO22646 | B30: Alpha | C30: Senior Lieutenant | D30: 4.44 | F30: 1039.2 | G30: 0 | H30: 64.7
A31: AO22701 | B31: Alpha | C31: Senior Lieutenant | D31: 4.18 | E31: 0.9 | F31: 375.5 | G31: 2 | H31: 40.7
A32: AO24250 | B32: Alpha | C32: Lieutenant | D32: 2.25 | E32: 1 | F32: 369.4 | G32: 4 | H32: 47.4
A33: AO22585 | B33: Alpha | C33: Senior Lieutenant | D33: 4.13 | E33: 0.94117647 | F33: 1266.6 | G33: 4 | H33: 29.7
A34: AO12461 | B34: Alpha | C34: Major | D34: 13.59 | E34: 1 | F34: 1728.9 | G34: 1 | H34: 62.1
A35: AO19336 | B35: Alpha | C35: Captain | D35: 7.05 | E35: 0.96153846 | F35: 1273.4 | G35: 1 | H35: 59.6
A36: AO17172 | B36: Alpha | C36: Captain | D36: 9.15 | E36: 1 | F36: 317.5 | G36: 0 | H36: 47.4
A37: AO22921 | B37: Alpha | C37: Senior Lieutenant | D37: 4.22 | E37: 0.88888889 | F37: 1304.3 | G37: 1 | H37: 53.4
A38: AO20473 | B38: Alpha | C38: Senior Lieutenant | D38: 5.91 | E38: 1 | F38: 920.8 | G38: 3 | H38: 54.8
A39: AO24361 | B39: Alpha | C39: Lieutenant | D39: 2 | F39: 389.1 | G39: 3 | H39: 54.9
A40: AO11628 | B40: Alpha | C40: Major | D40: 14.61 | E40: 0.91666667 | F40: 444.6 | G40: 1 | H40: 69
...

Sheet Rank_Rules
A1: rank | B1: min_staj_years | C1: max_staj_years
A2: Lieutenant | B2: 1 | C2: 3
A3: Senior Lieutenant | B3: 4 | C3: 6
A4: Captain | B4: 7 | C4: 11
A5: Major | B5: 12 | C5: 15
A6: Lieutenant Colonel | B6: 15 | C6: 30
A7: Junior Warrant Officer | B7: 1 | C7: 3
A8: Warrant Officer | B8: 3 | C8: 5
A9: Senior Warrant Officer | B9: 5 | C9: 20

Sheet Dept_Summary
A1: department | B1: headcount | C1: avg_flight_hours | D1: avg_success_rate | E1: avg_medal_count | F1: avg_risk_score
A2: Alpha | B2: =COUNTIF(Person_Data!$B$2:$B$526,A2) -> 105 | C2: =AVERAGEIF(Person_Data!$B$2:$B$526,A2,Person_Data!$F$2:$F$526) -> 492.59714 | D2: =AVERAGEIF(Person_Data!$B$2:$B$526,A2,Person_Data!$E$2:$E$526) -> 0.84280666 | E2: =AVERAGEIF(Person_Data!$B$2:$B$526,A2,Person_Data!$G$2:$G$526) -> 1.8 | F2: =AVERAGEIF(Person_Data!$B$2:$B$526,A2,Person_Data!$H$2:$H$526) -> 50.632381
A3: Beta | B3: =COUNTIF(Person_Data!$B$2:$B$526,A3) -> 105 | C3: =AVERAGEIF(Person_Data!$B$2:$B$526,A3,Person_Data!$F$2:$F$526) -> 472.6619 | D3: =AVERAGEIF(Person_Data!$B$2:$B$526,A3,Person_Data!$E$2:$E$526) -> 0.84427662 | E3: =AVERAGEIF(Person_Data!$B$2:$B$526,A3,Person_Data!$G$2:$G$526) -> 1.9142857 | F3: =AVERAGEIF(Person_Data!$B$2:$B$526,A3,Person_Data!$H$2:$H$526) -> 49.68381
A4: Delta | B4: =COUNTIF(Person_Data!$B$2:$B$526,A4) -> 105 | C4: =AVERAGEIF(Person_Data!$B$2:$B$526,A4,Person_Data!$F$2:$F$526) -> 497.88 | D4: =AVERAGEIF(Person_Data!$B$2:$B$526,A4,Person_Data!$E$2:$E$526) -> 0.82367174 | E4: =AVERAGEIF(Person_Data!$B$2:$B$526,A4,Person_Data!$G$2:$G$526) -> 1.5047619 | F4: =AVERAGEIF(Person_Data!$B$2:$B$526,A4,Person_Data!$H$2:$H$526) -> 51.918095
A5: Gamma | B5: =COUNTIF(Person_Data!$B$2:$B$526,A5) -> 105 | C5: =AVERAGEIF(Person_Data!$B$2:$B$526,A5,Person_Data!$F$2:$F$526) -> 471.37714 | D5: =AVERAGEIF(Person_Data!$B$2:$B$526,A5,Person_Data!$E$2:$E$526) -> 0.85870049 | E5: =AVERAGEIF(Person_Data!$B$2:$B$526,A5,Person_Data!$G$2:$G$526) -> 1.8952381 | F5: =AVERAGEIF(Person_Data!$B$2:$B$526,A5,Person_Data!$H$2:$H$526) -> 49.508571
A6: Sigma | B6: =COUNTIF(Person_Data!$B$2:$B$526,A6) -> 105 | C6: =AVERAGEIF(Person_Data!$B$2:$B$526,A6,Person_Data!$F$2:$F$526) -> 505.57333 | D6: =AVERAGEIF(Person_Data!$B$2:$B$526,A6,Person_Data!$E$2:$E$526) -> 0.85279572 | E6: =AVERAGEIF(Person_Data!$B$2:$B$526,A6,Person_Data!$G$2:$G$526) -> 1.1809524 | F6: =AVERAGEIF(Person_Data!$B$2:$B$526,A6,Person_Data!$H$2:$H$526) -> 48.190476

Sheet Risk_Watchlist
A1: person_id | B1: rank | C1: total_staj | D1: expected_min_staj | E1: expected_max_staj | F1: rank_staj_check | G1: risk_score | H1: risk_flag
A2: =Person_Data!A2 -> AO07216 | B2: =Person_Data!C2 -> Lieutenant Colonel | C2: =Person_Data!D2 -> 19.13 | D2: =INDEX(Rank_Rules!$B$2:$B$9,MATCH(B2,Rank_Rules!$A$2:$A$9,0)) -> 15 | E2: =INDEX(Rank_Rules!$C$2:$C$9,MATCH(B2,Rank_Rules!$A$2:$A$9,0)) -> 30 | F2: =IF(AND(C2>=D2,C2<=E2),"OK","MISMATCH") -> OK | G2: =Person_Data!H2 -> 83.9 | H2: =IF(G2>=65,"HIGH",IF(G2>=50,"MEDIUM","LOW")) -> HIGH
A3: =Person_Data!A3 -> AO12605 | B3: =Person_Data!C3 -> Major | C3: =Person_Data!D3 -> 14.03 | D3: =INDEX(Rank_Rules!$B$2:$B$9,MATCH(B3,Rank_Rules!$A$2:$A$9,0)) -> 12 | E3: =INDEX(Rank_Rules!$C$2:$C$9,MATCH(B3,Rank_Rules!$A$2:$A$9,0)) -> 15 | F3: =IF(AND(C3>=D3,C3<=E3),"OK","MISMATCH") -> OK | G3: =Person_Data!H3 -> 58.2 | H3: =IF(G3>=65,"HIGH",IF(G3>=50,"MEDIUM","LOW")) -> MEDIUM
A4: =Person_Data!A4 -> AO17018 | B4: =Person_Data!C4 -> Captain | C4: =Person_Data!D4 -> 8.69 | D4: =INDEX(Rank_Rules!$B$2:$B$9,MATCH(B4,Rank_Rules!$A$2:$A$9,0)) -> 7 | E4: =INDEX(Rank_Rules!$C$2:$C$9,MATCH(B4,Rank_Rules!$A$2:$A$9,0)) -> 11 | F4: =IF(AND(C4>=D4,C4<=E4),"OK","MISMATCH") -> OK | G4: =Person_Data!H4 -> 60.3 | H4: =IF(G4>=65,"HIGH",IF(G4>=50,"MEDIUM","LOW")) -> MEDIUM
A5: =Person_Data!A5 -> G22139 | B5: =Person_Data!C5 -> Warrant Officer | C5: =Person_Data!D5 -> 4.01 | D5: =INDEX(Rank_Rules!$B$2:$B$9,MATCH(B5,Rank_Rules!$A$2:$A$9,0)) -> 3 | E5: =INDEX(Rank_Rules!$C$2:$C$9,MATCH(B5,Rank_Rules!$A$2:$A$9,0)) -> 5 | F5: =IF(AND(C5>=D5,C5<=E5),"OK","MISMATCH") -> OK | G5: =Person_Data!H5 -> 55.4 | H5: =IF(G5>=65,"HIGH",IF(G5>=50,"MEDIUM","LOW")) -> MEDIUM
A6: =Person_Data!A6 -> AO16543 | B6: =Person_Data!C6 -> Captain | C6: =Person_Data!D6 -> 9.6 | D6: =INDEX(Rank_Rules!$B$2:$B$9,MATCH(B6,Rank_Rules!$A$2:$A$9,0)) -> 7 | E6: =INDEX(Rank_Rules!$C$2:$C$9,MATCH(B6,Rank_Rules!$A$2:$A$9,0)) -> 11 | F6: =IF(AND(C6>=D6,C6<=E6),"OK","MISMATCH") -> OK | G6: =Person_Data!H6 -> 48.1 | H6: =IF(G6>=65,"HIGH",IF(G6>=50,"MEDIUM","LOW")) -> LOW
A7: =Person_Data!A7 -> AO22963 | B7: =Person_Data!C7 -> Senior Lieutenant | C7: =Person_Data!D7 -> 4.44 | D7: =INDEX(Rank_Rules!$B$2:$B$9,MATCH(B7,Rank_Rules!$A$2:$A$9,0)) -> 4 | E7: =INDEX(Rank_Rules!$C$2:$C$9,MATCH(B7,Rank_Rules!$A$2:$A$9,0)) -> 6 | F7: =IF(AND(C7>=D7,C7<=E7),"OK","MISMATCH") -> OK | G7: =Person_Data!H7 -> 25.7 | H7: =IF(G7>=65,"HIGH",IF(G7>=50,"MEDIUM","LOW")) -> LOW
A8: =Person_Data!A8 -> AO19391 | B8: =Person_Data!C8 -> Captain | C8: =Person_Data!D8 -> 7.03 | D8: =INDEX(Rank_Rules!$B$2:$B$9,MATCH(B8,Rank_Rules!$A$2:$A$9,0)) -> 7 | E8: =INDEX(Rank_Rules!$C$2:$C$9,MATCH(B8,Rank_Rules!$A$2:$A$9,0)) -> 11 | F8: =IF(AND(C8>=D8,C8<=E8),"OK","MISMATCH") -> OK | G8: =Person_Data!H8 -> 33.7 | H8: =IF(G8>=65,"HIGH",IF(G8>=50,"MEDIUM","LOW")) -> LOW
A9: =Person_Data!A9 -> AO18976 | B9: =Person_Data!C9 -> Captain | C9: =Person_Data!D9 -> 8.36 | D9: =INDEX(Rank_Rules!$B$2:$B$9,MATCH(B9,Rank_Rules!$A$2:$A$9,0)) -> 7 | E9: =INDEX(Rank_Rules!$C$2:$C$9,MATCH(B9,Rank_Rules!$A$2:$A$9,0)) -> 11 | F9: =IF(AND(C9>=D9,C9<=E9),"OK","MISMATCH") -> OK | G9: =Person_Data!H9 -> 31.2 | H9: =IF(G9>=65,"HIGH",IF(G9>=50,"MEDIUM","LOW")) -> LOW
A10: =Person_Data!A10 -> AO13357 | B10: =Person_Data!C10 -> Major | C10: =Person_Data!D10 -> 13.01 | D10: =INDEX(Rank_Rules!$B$2:$B$9,MATCH(B10,Rank_Rules!$A$2:$A$9,0)) -> 12 | E10: =INDEX(Rank_Rules!$C$2:$C$9,MATCH(B10,Rank_Rules!$A$2:$A$9,0)) -> 15 | F10: =IF(AND(C10>=D10,C10<=E10),"OK","MISMATCH") -> OK | G10: =Person_Data!H10 -> 58.6 | H10: =IF(G10>=65,"HIGH",IF(G10>=50,"MEDIUM","LOW")) -> MEDIUM
A11: =Person_Data!A11 -> AO23290 | B11: =Person_Data!C11 -> Lieutenant | C11: =Person_Data!D11 -> 2.69 | D11: =INDEX(Rank_Rules!$B$2:$B$9,MATCH(B11,Rank_Rules!$A$2:$A$9,0)) -> 1 | E11: =INDEX(Rank_Rules!$C$2:$C$9,MATCH(B11,Rank_Rules!$A$2:$A$9,0)) -> 3 | F11: =IF(AND(C11>=D11,C11<=E11),"OK","MISMATCH") -> OK | G11: =Person_Data!H11 -> 47.1 | H11: =IF(G11>=65,"HIGH",IF(G11>=50,"MEDIUM","LOW")) -> LOW
A12: =Person_Data!A12 -> AO16547 | B12: =Person_Data!C12 -> Captain | C12: =Person_Data!D12 -> 9.92 | D12: =INDEX(Rank_Rules!$B$2:$B$9,MATCH(B12,Rank_Rules!$A$2:$A$9,0)) -> 7 | E12: =INDEX(Rank_Rules!$C$2:$C$9,MATCH(B12,Rank_Rules!$A$2:$A$9,0)) -> 11 | F12: =IF(AND(C12>=D12,C12<=E12),"OK","MISMATCH") -> OK | G12: =Person_Data!H12 -> 69.1 | H12: =IF(G12>=65,"HIGH",IF(G12>=50,"MEDIUM","LOW")) -> HIGH
A13: =Person_Data!A13 -> AO13497 | B13: =Person_Data!C13 -> Major | C13: =Person_Data!D13 -> 13.14 | D13: =INDEX(Rank_Rules!$B$2:$B$9,MATCH(B13,Rank_Rules!$A$2:$A$9,0)) -> 12 | E13: =INDEX(Rank_Rules!$C$2:$C$9,MATCH(B13,Rank_Rules!$A$2:$A$9,0)) -> 15 | F13: =IF(AND(C13>=D13,C13<=E13),"OK","MISMATCH") -> OK | G13: =Person_Data!H13 -> 51.3 | H13: =IF(G13>=65,"HIGH",IF(G13>=50,"MEDIUM","LOW")) -> MEDIUM
... A526: =Person_Data!A526 -> G22986 | B526: =Person_Data!C526 -> Warrant Officer | C526: =Person_Data!D526 -> 4.37 | D526: =INDEX(Rank_Rules!$B$2:$B$9,MATCH(B526,Rank_Rules!$A$2:$A$9,0)) -> 3 | E526: =INDEX(Rank_Rules!$C$2:$C$9,MATCH(B526,Rank_Rules!$A$2:$A$9,0)) -> 5 | F526: =IF(AND(C526>=D526,C526<=E526),"OK","MISMATCH") -> OK | G526: =Person_Data!H526 -> 48.1 | H526: =IF(G526>=65,"HIGH",IF(G526>=50,"MEDIUM","LOW")) -> LOW
